Workbook

Sheet mapping_overview
A1: Variable | C1: GHG Emissions (average kg CO2 / household) | D1: 0000 | E1: 0100 | F1: 0200 | G1: 0204 | H1: 0230 | I1: 0300 | J1: 0310 | K1: 0320 | L1: 1000 | M1: 2000 | N1: 3000 | O1: 3100 | P1: 3200 | Q1: 3300 | R1: 3310 | S1: 3400 | T1: 3430 | U1: 3500 | V1: 3540 | W1: 3600 | X1: 3610 | Y1: 3620 | Z1: 3630 | AA1: 3700 | AB1: 3800 | AC1: 3830 | AD1: 3900 | AE1: 4000 | AF1: 4100 | AG1: 4200 | AH1: 4300 | AI1: 5000 | AJ1: 5100 | AK1: 5140 | AL1: 5200 | AM1: 5300 | AN1: 6000 | AO1: 6100 | AP1: 6200 | AQ1: 6300 | AR1: 7000 | AS1: 7100 | AT1: 7130 | AU1: 7200 | AV1: 7300 | AW1: 7330 | AX1: 8000 | AY1: 8100 | AZ1: 8200 | BA1: 9900
D2: Persoonlijke verzorging, ongespecificeerd | E2: In bed | F2: Eten, ongespecificeerd | G2: Eten, ongespecificeerd - werk / school (kantine) | H2: Iets drinken, ongespecificeerd | I2: Overige persoonlijke verzorging, ongespecificeerd ("verzorgen") | J2: Wassen en aankleden, ongespecificeerd | K2: Medische verzorging | L2: Betaald werk | M2: Studie | N2: Huishouden en zorg voor gezin, ongespecificeerd | O2: Eten bereiden, ongespecificeerd | P2: Huishouden, schoonmaken, ongespecificeerd | Q2: Kleding fabricage en onderhoud, ongespecificeerd | R2: Kleren wassen, was ophangen, was opbergen, wasserette, in droger | S2: Tuinieren en zorg voor dieren, ongespecificeerd | T2: Huisdieren verzorgen (poes, hamster, vis, hond) & Hond uitlaten | U2: Doe het zelf en onderhoud, ongespecificeerd (klussen in huis) | V2: Onderhoud en reparatie, van vervoersmiddelen, ongespecificeerd | W2: Winkels en diensten, ongespecificeerd | X2: Boodschappen, winkelen, ongespecificeerd | Y2: Commerciele en administratieve diensten, ongespecificeerd | Z2: Persoonlijke diensten, ongespecificeerd | AA2: Huishouden organisatie, ongespecificeerd | AB2: Zorg voor kinderen, ongespecificeerd | AC2: Voorlezen, spelen en praten met kind | AD2: Zorg voor volwassenen ongespecificeerd | AE2: Vrijwilligerswerk, hulp, vergaderingen en religie, ongespecificeerd | AF2: Vrijwilligerswerk voor/in een organisatie, ongespecificeerd | AG2: Hulp in ander huishouden | AH2: Participatorische activiteiten, ongespecificeerd | AI2: Sociaal leven en vermaak, ongespecificeerd | AJ2: Sociaal leven, ongespecificeerd | AK2: Telefoon, ongespecificeerd | AL2: Vermaak en cultuur, ongespecificeerd | AM2: Uitrusten | AN2: Sport en lichaamsbeweging, ongespecificeerd | AO2: Actieve vrijetijdsbesteding, ongespecificeerd | AP2: Actieve productieve activiteiten, ongespecificeerd | AQ2: Sport gerelateerde activiteiten | AR2: Hobby en computeren, ongespecificeerd | AS2: Kunst, amateurkunst en hobbies, ongespecificeerd | AT2: Correspondentie | AU2: Computeren, ongespecificeerd | AV2: Spelletjes, games, ongespecificeerd | AW2: Computer spelen, games | AX2: Massa media, ongespecificeerd | AY2: Lezen, ongespecificeerd | AZ2: Audiovisueel media, ongespecificeerd | BA2: Overig
A3: BOBEST011100H | B3: Brood en granen | C3: =emissions!B2 -> 0 | D3: 1 | F3: 1 | N3: 1 | AB3: 1
A4: BOBEST011110H | B4: Rijst | C4: =emissions!B3 -> 0 | D4: 1 | F4: 1 | N4: 1 | AB4: 1
A5: BOBEST011170H | B5: Ontbijtgranen | C5: =emissions!B4 -> 0 | D5: 1 | F5: 1 | N5: 1 | AB5: 1
A6: BOBEST011200H | B6: Vlees | C6: =emissions!B5 -> 0 | D6: 1 | F6: 1 | N6: 1 | AB6: 1
A7: BOBEST011210H | B7: Rund- en kalfsvlees | C7: =emissions!B6 -> 0 | D7: 1 | F7: 1 | N7: 1 | AB7: 1
A8: BOBEST011220H | B8: Varkensvlees | C8: =emissions!B7 -> 0 | D8: 1 | F8: 1 | N8: 1 | AB8: 1
A9: BOBEST011240H | B9: Pluimveevlees | C9: =emissions!B8 -> 0 | D9: 1 | F9: 1 | N9: 1 | AB9: 1
A10: BOBEST011300H | B10: Vis en schaal- en schelpdieren | C10: =emissions!B9 -> 0 | D10: 1 | F10: 1 | N10: 1 | AB10: 1
A11: BOBEST011400H | B11: Melk, kaas en eieren | C11: =emissions!B10 -> 0 | D11: 1 | F11: 1 | N11: 1 | AB11: 1
A12: BOBEST011410H | B12: Verse volle melk | C12: =emissions!B11 -> 0 | D12: 1 | F12: 1 | N12: 1 | AB12: 1
A13: BOBEST011420H | B13: Verse halfvolle en magere melk | C13: =emissions!B12 -> 0 | D13: 1 | F13: 1 | N13: 1 | AB13: 1
A14: BOBEST011430H | B14: Houdbare melk | C14: =emissions!B13 -> 0 | D14: 1 | F14: 1 | N14: 1 | AB14: 1
... A19: BOBEST011900H | B19: Voedingsmiddelen niet elders genoemd | C19: =emissions!B18 -> 0 | D19: 1 | F19: 1 | N19: 1 | AB19: 1
A20: BOBEST012110H | B20: Koffie | C20: =emissions!B19 -> 0 | D20: 1 | F20: 1 | H20: 1 | N20: 1 | AB20: 1
A21: BOBEST012120H | B21: Thee | C21: =emissions!B20 -> 0 | D21: 1 | F21: 1 | H21: 1 | N21: 1 | AB21: 1
A22: BOBEST012130H | B22: Cacao en chocolade in poedervorm | C22: =emissions!B21 -> 0 | D22: 1 | F22: 1 | H22: 1 | N22: 1 | AB22: 1
A23: BOBEST012210H | B23: Mineraalwater of bronwater | C23: =emissions!B22 -> 0 | D23: 1 | F23: 1 | H23: 1 | N23: 1 | AB23: 1
A24: BOBEST012220H | B24: Frisdranken | C24: =emissions!B23 -> 0 | D24: 1 | F24: 1 | H24: 1 | N24: 1 | AB24: 1
A25: BOBEST012230H | B25: Vruchten- en groentesappen | C25: =emissions!B24 -> 0 | D25: 1 | F25: 1 | H25: 1 | N25: 1 | AB25: 1
A26: BOBEST021100H | B26: Gedistilleerde dranken | C26: =emissions!B25 -> 0 | D26: 1 | F26: 1 | H26: 1
A27: BOBEST021200H | B27: Wijn | C27: =emissions!B26 -> 0 | D27: 1 | F27: 1 | H27: 1
A28: BOBEST021300H | B28: Bier | C28: =emissions!B27 -> 0 | D28: 1 | F28: 1 | H28: 1
A29: BOBEST022000H | B29: Tabak | C29: =emissions!B28 -> 0 | D29: 1 | F29: 1 | H29: 1 | I29: 1 | J29: 1 | K29: 1 | N29: 1 | O29: 1 | P29: 1 | Q29: 1 | R29: 1 | S29: 1 | T29: 1 | U29: 1 | V29: 1 | W29: 1 | X29: 1 | Y29: 1 | Z29: 1 | AA29: 1 | AB29: 1 | AC29: 1 | AD29: 1 | AE29: 1 | AF29: 1 | AG29: 1 | AH29: 1 | AI29: 1 | AJ29: 1 | AK29: 1 | AL29: 1 | AM29: 1 | AN29: 1 | AP29: 1 | AR29: 1 | AS29: 1 | AT29: 1 | AU29: 1 | AV29: 1 | AW29: 1 | AX29: 1 | AY29: 1 | AZ29: 1 | BA29: 1
A30: BOBEST023000H | B30: Verdovende middelen | C30: =emissions!B29 -> 0 | D30: 1 | F30: 1
A31: BOBEST031100H | B31: Kledingstoffen | C31: =emissions!B30 -> 0 | N31: 1 | Q31: 1
A32: BOBEST031200H | B32: Kleding | C32: =emissions!B31 -> 0 | D32: 1 | J32: 1
A33: BOBEST031300H | B33: Overige kledingartikelen en toebehoren | C33: =emissions!B32 -> 0 | D33: 1 | J33: 1 | N33: 1 | Q33: 1
A34: BOBEST031400H | B34: Stomen en reparatie van kleding | C34: =emissions!B33 -> 0 | N34: 1 | Q34: 1 | W34: 1 | X34: 1
A35: BOBEST032100H | B35: Schoenen en ander schoeisel | C35: =emissions!B34 -> 0 | D35: 1 | J35: 1
A36: BOBEST032200H | B36: Reparatie en verhuur van schoenen | C36: =emissions!B35 -> 0 | N36: 1 | Q36: 1 | W36: 1 | X36: 1
A37: BOBEST041100H | B37: Werkelijke woninghuur betaald door huurders | C37: =emissions!B36 -> 0
A38: BOBEST041200H | B38: Overige werkelijke woninghuur | C38: =emissions!B37 -> 0
A39: BOBEST042100H | B39: Toegerekende huur eigen woning | C39: =emissions!B38 -> 0
A40: BOBEST042200H | B40: Overige toegerekende huur | C40: =emissions!B39 -> 0
A41: BOBEST043100H | B41: Onderhoudsmaterialen voor de woning | C41: =emissions!B40 -> 0 | N41: 1 | U41: 1
A42: BOBEST043200H | B42: Onderhoudsdiensten voor de woning | C42: =emissions!B41 -> 0 | N42: 1 | U42: 1
A43: BOBEST044100H | B43: Watervoorziening | C43: =emissions!B42 -> 0 | D43: 1 | I43: 1 | J43: 1 | K43: 1 | N43: 1 | O43: 1 | P43: 1 | Q43: 1 | R43: 1 | S43: 1 | T43: 1 | U43: 1 | V43: 1 | AB43: 1 | AD43: 1
A44: BOBEST044200H | B44: Ophalen van huisvuil | C44: =emissions!B43 -> 0
...

Sheet mapping_relative
A1: Column1 | B1: activity_11_0 | C1: activity_11_110 | D1: activity_11_120 | E1: activity_11_130 | F1: activity_11_190 | G1: activity_11_200 | H1: activity_11_210 | I1: activity_11_220 | J1: activity_11_230 | K1: activity_11_290 | L1: activity_11_300 | M1: activity_11_310 | N1: activity_11_320 | O1: activity_11_330 | P1: activity_11_390 | Q1: activity_11_3000 | R1: activity_11_3110 | S1: activity_11_3120 | T1: activity_11_3130 | U1: activity_11_3140 | V1: activity_11_3190 | W1: activity_11_3200 | X1: activity_11_3210 | Y1: activity_11_3220 | Z1: activity_11_3230 | AA1: activity_11_3240 | AB1: activity_11_3290 | AC1: activity_11_3300 | AD1: activity_11_3310 | AE1: activity_11_3320 | AF1: activity_11_3330 | AG1: activity_11_3390 | AH1: activity_11_3400 | AI1: activity_11_3410 | AJ1: activity_11_3420 | AK1: activity_11_3430 | AL1: activity_11_3440 | AM1: activity_11_3490 | AN1: activity_11_3500 | AO1: activity_11_3510 | AP1: activity_11_3520 | AQ1: activity_11_3530 | AR1: activity_11_3540 | AS1: activity_11_3590 | AT1: activity_11_3600 | AU1: activity_11_3610 | AV1: activity_11_3620 | AW1: activity_11_3630 | AX1: activity_11_3690 | AY1: activity_11_3710 | AZ1: activity_11_3800 | BA1: activity_11_3810 | BB1: activity_11_3820 | BC1: activity_11_3830 | BD1: activity_11_3840 | BE1: activity_11_3890 | BF1: activity_11_3910 | BG1: activity_11_3920 | BH1: activity_11_3990 | BI1: activity_11_4000 | BJ1: activity_11_4100 | BK1: activity_11_4110 | BL1: activity_11_4120 | BM1: activity_11_4210 | BN1: activity_11_4220 | BO1: activity_11_4230 | BP1: activity_11_4240 | BQ1: activity_11_4250 | BR1: activity_11_4290 | BS1: activity_11_4300 | BT1: activity_11_4310 | BU1: activity_11_4320 | BV1: activity_11_4390 | BW1: activity_11_5000 | BX1: activity_11_5100 | BY1: activity_11_5110 | BZ1: activity_11_5120 | CA1: activity_11_5130 | CB1: activity_11_5140 | CC1: activity_11_5190 | CD1: activity_11_5200 | CE1: activity_11_5210 | CF1: activity_11_5220 | CG1: activity_11_5230 | CH1: activity_11_5240 | CI1: activity_11_5250 | CJ1: activity_11_5260 | CK1: activity_11_5290 | CL1: activity_11_5310 | CM1: activity_11_6000 | CN1: activity_11_6100 | CO1: activity_11_6110 | CP1: activity_11_6120 | CQ1: activity_11_6130 | CR1: activity_11_6140 | CS1: activity_11_6150 | CT1: activity_11_6160 | CU1: activity_11_6190 | CV1: activity_11_6200 | CW1: activity_11_6210 | CX1: activity_11_6220 | CY1: activity_11_6290 | CZ1: activity_11_6310 | DA1: activity_11_7000 | DB1: activity_11_7100 | DC1: activity_11_7110 | DD1: activity_11_7120 | DE1: activity_11_7130 | DF1: activity_11_7190 | DG1: activity_11_7200 | DH1: activity_11_7210 | DI1: activity_11_7220 | DJ1: activity_11_7230 | DK1: activity_11_7250 | DL1: activity_11_7290 | DM1: activity_11_7300 | DN1: activity_11_7310 | DO1: activity_11_7320 | DP1: activity_11_7330 | DQ1: activity_11_7390 | DR1: activity_11_8000 | DS1: activity_11_8100 | DT1: activity_11_8110 | DU1: activity_11_8120 | DV1: activity_11_8190 | DW1: activity_11_8210 | DX1: activity_11_8220 | DY1: activity_11_8300 | DZ1: activity_11_8310 | EA1: activity_11_8320 | EB1: activity_11_9950 | EC1: activity_11_9980 | ED1: activity_11_9990 | EE1: activity_10_0 | EF1: activity_10_110 | EG1: activity_10_120 | EH1: activity_10_130 | EI1: activity_10_190 | EJ1: activity_10_200 | EK1: activity_10_210 | EL1: activity_10_220 | EM1: activity_10_230 | EN1: activity_10_290 | EO1: activity_10_300 | EP1: activity_10_310 | EQ1: activity_10_320 | ER1: activity_10_330 | ES1: activity_10_390 | ET1: activity_10_3000 | EU1: activity_10_3110 | EV1: activity_10_3120 | EW1: activity_10_3130 | EX1: activity_10_3140 | EY1: activity_10_3190 | EZ1: activity_10_3200 | FA1: activity_10_3210 | FB1: activity_10_3220 | FC1: activity_10_3230 | FD1: activity_10_3240 | FE1: activity_10_3290 | FF1: activity_10_3300 | FG1: activity_10_3310 | FH1: activity_10_3320 | FI1: activity_10_3330 | FJ1: activity_10_3390 | FK1: activity_10_3400 | FL1: activity_10_3410 | FM1: activity_10_3420 | FN1: activity_10_3430 | FO1: activity_10_3440 | FP1: activity_10_3490 | FQ1: activity_10_3500 | FR1: activity_10_3510 | FS1: activity_10_3520 | FT1: activity_10_3530 | FU1: activity_10_3540 | FV1: activity_10_3590 | FW1: activity_10_3600 | FX1: activity_10_3610 | FY1: activity_10_3620 | FZ1: activity_10_3630 | GA1: activity_10_3690 | GB1: activity_10_3710 | GC1: activity_10_3800 | GD1: activity_10_3810 | GE1: activity_10_3820 | GF1: activity_10_3830 | GG1: activity_10_3840 | GH1: activity_10_3890 | GI1: activity_10_3910 | GJ1: activity_10_3920 | GK1: activity_10_3990 | GL1: activity_10_4000 | GM1: activity_10_4100 | GN1: activity_10_4110 | GO1: activity_10_4120 | GP1: activity_10_4210 | GQ1: activity_10_4220 | GR1: activity_10_4230 | GS1: activity_10_4240 | GT1: activity_10_4250 | GU1: activity_10_4290 | GV1: activity_10_4300 | GW1: activity_10_4310 | GX1: activity_10_4320 | GY1: activity_10_4390 | GZ1: activity_10_5000 | HA1: activity_10_5100 | HB1: activity_10_5110 | HC1: activity_10_5120 | HD1: activity_10_5130 | HE1: activity_10_5140 | HF1: activity_10_5190 | HG1: activity_10_5200 | HH1: activity_10_5210 | HI1: activity_10_5220 | HJ1: activity_10_5230 | HK1: activity_10_5240 | HL1: activity_10_5250 | HM1: activity_10_5260 | HN1: activity_10_5290 | HO1: activity_10_5310 | HP1: activity_10_6000 | HQ1: activity_10_6100 | HR1: activity_10_6110 | HS1: activity_10_6120 | HT1: activity_10_6130 | HU1: activity_10_6140 | HV1: activity_10_6150 | HW1: activity_10_6160 | HX1: activity_10_6190 | HY1: activity_10_6200 | HZ1: activity_10_6210 | IA1: activity_10_6220 | IB1: activity_10_6290 | IC1: activity_10_6310 | ID1: activity_10_7000 | IE1: activity_10_7100 | IF1: activity_10_7110 | IG1: activity_10_7120 | IH1: activity_10_7130 | II1: activity_10_7190 | IJ1: activity_10_7200 | IK1: activity_10_7210 | IL1: activity_10_7220 | IM1: activity_10_7230 | IN1: activity_10_7250 | IO1: activity_10_7290 | IP1: activity_10_7300 | IQ1: activity_10_7310 | IR1: activity_10_7320 | IS1: activity_10_7330 | IT1: activity_10_7390 | IU1: activity_10_8000 | IV1: activity_10_8100 | IW1: activity_10_8110 | IX1: activity_10_8120 | IY1: activity_10_8190 | IZ1: activity_10_8210 | JA1: activity_10_8220 | JB1: activity_10_8300 | JC1: activity_10_8310 | JD1: activity_10_8320 | JE1: activity_10_9950 | JF1: activity_10_9980 | JG1: activity_10_9990 | JH1: activity_20_9000 | JI1: activity_21_9000 | JJ1: activity_22_9000 | JK1: activity_23_9000 | JL1: activity_24_9000 | JM1: activity_25_9000 | JN1: activity_26_9000 | JO1: activity_20_9360 | JP1: activity_21_9360 | JQ1: activity_22_9360 | JR1: activity_23_9360 | JS1: activity_24_9360 | JT1: activity_25_9360 | JU1: activity_26_9360 | JV1: activity_20_9380 | JW1: activity_21_9380 | JX1: activity_22_9380 | JY1: activity_23_9380 | JZ1: activity_24_9380 | KA1: activity_25_9380 | KB1: activity_26_9380 | KC1: activity_20_9400 | KD1: activity_21_9400 | KE1: activity_22_9400 | KF1: activity_23_9400 | KG1: activity_24_9400 | KH1: activity_25_9400 | KI1: activity_26_9400 | KJ1: activity_20_9500 | KK1: activity_21_9500 | KL1: activity_22_9500 | KM1: activity_23_9500 | KN1: activity_24_9500 | KO1: activity_25_9500 | KP1: activity_26_9500 | KQ1: activity_20_9600 | KR1: activity_21_9600 | KS1: activity_22_9600 | KT1: activity_23_9600 | KU1: activity_24_9600 | KV1: activity_25_9600 | KW1: activity_26_9600 | KX1: activity_20_9800 | KY1: activity_21_9800 | KZ1: activity_22_9800 | LA1: activity_23_9800 | LB1: activity_24_9800 | LC1: activity_25_9800 | LD1: activity_26_9800
A2: BOBEST011100H
A3: BOBEST011110H
A4: BOBEST011170H
A5: BOBEST011200H
A6: BOBEST011210H
A7: BOBEST011220H
A8: BOBEST011240H
A9: BOBEST011300H
A10: BOBEST011400H
A11: BOBEST011410H
A12: BOBEST011420H
A13: BOBEST011430H
... A157: BOBEST300000H

Sheet mapping_home
A1: Variable | C1: =CONCATENATE(mapping_overview!D1, "_11") -> 0000_11 | D1: =CONCATENATE(mapping_overview!E1, "_11") -> 0100_11 | E1: =CONCATENATE(mapping_overview!F1, "_11") -> 0200_11 | F1: =CONCATENATE(mapping_overview!G1, "_11") -> 0204_11 | G1: =CONCATENATE(mapping_overview!H1, "_11") -> 0230_11 | H1: =CONCATENATE(mapping_overview!I1, "_11") -> 0300_11 | I1: =CONCATENATE(mapping_overview!J1, "_11") -> 0310_11 | J1: =CONCATENATE(mapping_overview!K1, "_11") -> 0320_11 | ... AZ1: =CONCATENATE(mapping_overview!BA1, "_11") -> 9900_11
C2: =mapping_overview!D2 -> Persoonlijke verzorging, ongespecificeerd | D2: =mapping_overview!E2 -> In bed | E2: =mapping_overview!F2 -> Eten, ongespecificeerd | F2: =mapping_overview!G2 -> Eten, ongespecificeerd - werk / school (kantine) | G2: =mapping_overview!H2 -> Iets drinken, ongespecificeerd | H2: =mapping_overview!I2 -> Overige persoonlijke verzorging, ongespecificeerd ("verzorgen") | I2: =mapping_overview!J2 -> Wassen en aankleden, ongespecificeerd | J2: =mapping_overview!K2 -> Medische verzorging | ... AZ2: =mapping_overview!BA2 -> Overig
A3: BOBEST011100H | B3: Brood en granen
A4: BOBEST011110H | B4: Rijst
A5: BOBEST011170H | B5: Ontbijtgranen
A6: BOBEST011200H | B6: Vlees
A7: BOBEST011210H | B7: Rund- en kalfsvlees
A8: BOBEST011220H | B8: Varkensvlees
A9: BOBEST011240H | B9: Pluimveevlees
A10: BOBEST011300H | B10: Vis en schaal- en schelpdieren
A11: BOBEST011400H | B11: Melk, kaas en eieren
A12: BOBEST011410H | B12: Verse volle melk
A13: BOBEST011420H | B13: Verse halfvolle en magere melk
A14: BOBEST011430H | B14: Houdbare melk
... A158: BOBEST300000H | B158: Uitgaven aan groot onderhoud

Sheet mapping_out
A1: Variable | C1: =CONCATENATE(mapping_overview!D1, "_10") -> 0000_10 | D1: =CONCATENATE(mapping_overview!E1, "_10") -> 0100_10 | E1: =CONCATENATE(mapping_overview!F1, "_10") -> 0200_10 | F1: =CONCATENATE(mapping_overview!G1, "_10") -> 0204_10 | G1: =CONCATENATE(mapping_overview!H1, "_10") -> 0230_10 | H1: =CONCATENATE(mapping_overview!I1, "_10") -> 0300_10 | I1: =CONCATENATE(mapping_overview!J1, "_10") -> 0310_10 | J1: =CONCATENATE(mapping_overview!K1, "_10") -> 0320_10 | ... AZ1: =CONCATENATE(mapping_overview!BA1, "_10") -> 9900_10
C2: =mapping_overview!D2 -> Persoonlijke verzorging, ongespecificeerd | D2: =mapping_overview!E2 -> In bed | E2: =mapping_overview!F2 -> Eten, ongespecificeerd | F2: =mapping_overview!G2 -> Eten, ongespecificeerd - werk / school (kantine) | G2: =mapping_overview!H2 -> Iets drinken, ongespecificeerd | H2: =mapping_overview!I2 -> Overige persoonlijke verzorging, ongespecificeerd ("verzorgen") | I2: =mapping_overview!J2 -> Wassen en aankleden, ongespecificeerd | J2: =mapping_overview!K2 -> Medische verzorging | ... AZ2: =mapping_overview!BA2 -> Overig
A3: BOBEST011100H | B3: Brood en granen
A4: BOBEST011110H | B4: Rijst
A5: BOBEST011170H | B5: Ontbijtgranen
A6: BOBEST011200H | B6: Vlees
A7: BOBEST011210H | B7: Rund- en kalfsvlees
A8: BOBEST011220H | B8: Varkensvlees
A9: BOBEST011240H | B9: Pluimveevlees
A10: BOBEST011300H | B10: Vis en schaal- en schelpdieren
A11: BOBEST011400H | B11: Melk, kaas en eieren
A12: BOBEST011410H | B12: Verse volle melk
A13: BOBEST011420H | B13: Verse halfvolle en magere melk
A14: BOBEST011430H | B14: Houdbare melk
... A158: BOBEST300000H | B158: Uitgaven aan groot onderhoud

Sheet mapping_transport
A1: Variable | C1: 9000_20 | D1: 9000_21 | E1: 9000_22 | F1: 9000_23 | G1: 9000_24 | H1: 9000_25 | I1: 9000_26 | J1: 9100_20 | K1: 9100_21 | L1: 9100_22 | M1: 9100_23 | N1: 9100_24 | O1: 9100_25 | P1: 9100_26 | Q1: 9200_20 | R1: 9200_21 | S1: 9200_22 | T1: 9200_23 | U1: 9200_24 | V1: 9200_25 | W1: 9200_26 | X1: 9360_20 | Y1: 9360_21 | Z1: 9360_22 | AA1: 9360_23 | AB1: 9360_24 | AC1: 9360_25 | AD1: 9360_26 | AE1: 9380_20 | AF1: 9380_21 | AG1: 9380_22 | AH1: 9380_23 | AI1: 9380_24 | AJ1: 9380_25 | AK1: 9380_26 | AL1: 9400_20 | AM1: 9400_21 | AN1: 9400_22 | AO1: 9400_23 | AP1: 9400_24 | AQ1: 9400_25 | AR1: 9400_26 | AS1: 9500_20 | AT1: 9500_21 | AU1: 9500_22 | AV1: 9500_23 | AW1: 9500_24 | AX1: 9500_25 | AY1: 9500_26 | AZ1: 9600_20 | BA1: 9600_21 | BB1: 9600_22 | BC1: 9600_23 | BD1: 9600_24 | BE1: 9600_25 | BF1: 9600_26 | BG1: 9800_20 | BH1: 9800_21 | BI1: 9800_22 | BJ1: 9800_23 | BK1: 9800_24 | BL1: 9800_25 | BM1: 9800_26
C2: Andere of niet gespecificeerde verplaatsing | D2: Andere of niet gespecificeerde verplaatsing | E2: Andere of niet gespecificeerde verplaatsing | F2: Andere of niet gespecificeerde verplaatsing | G2: Andere of niet gespecificeerde verplaatsing | H2: Andere of niet gespecificeerde verplaatsing | I2: Andere of niet gespecificeerde verplaatsing | J2: Verplaatsing van en naar werk | K2: Verplaatsing van en naar werk | L2: Verplaatsing van en naar werk | M2: Verplaatsing van en naar werk | N2: Verplaatsing van en naar werk | O2: Verplaatsing van en naar werk | P2: Verplaatsing van en naar werk | Q2: Verplaatsing van en naar school of studie | R2: Verplaatsing van en naar school of studie | S2: Verplaatsing van en naar school of studie | T2: Verplaatsing van en naar school of studie | U2: Verplaatsing van en naar school of studie | V2: Verplaatsing van en naar school of studie | W2: Verplaatsing van en naar school of studie | X2: Verplaatsing van en naar winkels en diensten | Y2: Verplaatsing van en naar winkels en diensten | Z2: Verplaatsing van en naar winkels en diensten | AA2: Verplaatsing van en naar winkels en diensten | AB2: Verplaatsing van en naar winkels en diensten | AC2: Verplaatsing van en naar winkels en diensten | AD2: Verplaatsing van en naar winkels en diensten | AE2: Verplaatsing tbv andere huishoudelijke activiteit | AF2: Verplaatsing tbv andere huishoudelijke activiteit | AG2: Verplaatsing tbv andere huishoudelijke activiteit | AH2: Verplaatsing tbv andere huishoudelijke activiteit | AI2: Verplaatsing tbv andere huishoudelijke activiteit | AJ2: Verplaatsing tbv andere huishoudelijke activiteit | AK2: Verplaatsing tbv andere huishoudelijke activiteit | AL2: Verplaatsing tbv vrijwilligerswerk of bijeenkomsten | AM2: Verplaatsing tbv vrijwilligerswerk of bijeenkomsten | AN2: Verplaatsing tbv vrijwilligerswerk of bijeenkomsten | AO2: Verplaatsing tbv vrijwilligerswerk of bijeenkomsten | AP2: Verplaatsing tbv vrijwilligerswerk of bijeenkomsten | AQ2: Verplaatsing tbv vrijwilligerswerk of bijeenkomsten | AR2: Verplaatsing tbv vrijwilligerswerk of bijeenkomsten | AS2: verplaatsing tbv sociaal leven | AT2: verplaatsing tbv sociaal leven | AU2: verplaatsing tbv sociaal leven | AV2: verplaatsing tbv sociaal leven | AW2: verplaatsing tbv sociaal leven | AX2: verplaatsing tbv sociaal leven | AY2: verplaatsing tbv sociaal leven | AZ2: Verplaatsing tbv ander vrijetijdsbesteding | BA2: Verplaatsing tbv ander vrijetijdsbesteding | BB2: Verplaatsing tbv ander vrijetijdsbesteding | BC2: Verplaatsing tbv ander vrijetijdsbesteding | BD2: Verplaatsing tbv ander vrijetijdsbesteding | BE2: Verplaatsing tbv ander vrijetijdsbesteding | BF2: Verplaatsing tbv ander vrijetijdsbesteding | BG2: Verplaatsing tbv verandering locatie | BH2: Verplaatsing tbv verandering locatie | BI2: Verplaatsing tbv verandering locatie | BJ2: Verplaatsing tbv verandering locatie | BK2: Verplaatsing tbv verandering locatie | BL2: Verplaatsing tbv verandering locatie | BM2: Verplaatsing tbv verandering locatie
A3: BOBEST011100H | B3: Brood en granen | C3: =IF(SUM(D3:I3)>0, 1, "") | J3: =IF(SUM(K3:P3)>0, 1, "") | Q3: =IF(SUM(R3:W3)>0, 1, "") | X3: =IF(SUM(Y3:AD3)>0, 1, "") | AE3: =IF(SUM(AF3:AK3)>0, 1, "") | AL3: =IF(SUM(AM3:AR3)>0, 1, "") | AS3: =IF(SUM(AT3:AY3)>0, 1, "") | AZ3: =IF(SUM(BA3:BF3)>0, 1, "") | BG3: =IF(SUM(BH3:BM3)>0, 1, "")
A4: BOBEST011110H | B4: Rijst | C4: =IF(SUM(D4:I4)>0, 1, "") | J4: =IF(SUM(K4:P4)>0, 1, "") | Q4: =IF(SUM(R4:W4)>0, 1, "") | X4: =IF(SUM(Y4:AD4)>0, 1, "") | AE4: =IF(SUM(AF4:AK4)>0, 1, "") | AL4: =IF(SUM(AM4:AR4)>0, 1, "") | AS4: =IF(SUM(AT4:AY4)>0, 1, "") | AZ4: =IF(SUM(BA4:BF4)>0, 1, "") | BG4: =IF(SUM(BH4:BM4)>0, 1, "")
A5: BOBEST011170H | B5: Ontbijtgranen | C5: =IF(SUM(D5:I5)>0, 1, "") | J5: =IF(SUM(K5:P5)>0, 1, "") | Q5: =IF(SUM(R5:W5)>0, 1, "") | X5: =IF(SUM(Y5:AD5)>0, 1, "") | AE5: =IF(SUM(AF5:AK5)>0, 1, "") | AL5: =IF(SUM(AM5:AR5)>0, 1, "") | AS5: =IF(SUM(AT5:AY5)>0, 1, "") | AZ5: =IF(SUM(BA5:BF5)>0, 1, "") | BG5: =IF(SUM(BH5:BM5)>0, 1, "")
A6: BOBEST011200H | B6: Vlees | C6: =IF(SUM(D6:I6)>0, 1, "") | J6: =IF(SUM(K6:P6)>0, 1, "") | Q6: =IF(SUM(R6:W6)>0, 1, "") | X6: =IF(SUM(Y6:AD6)>0, 1, "") | AE6: =IF(SUM(AF6:AK6)>0, 1, "") | AL6: =IF(SUM(AM6:AR6)>0, 1, "") | AS6: =IF(SUM(AT6:AY6)>0, 1, "") | AZ6: =IF(SUM(BA6:BF6)>0, 1, "") | BG6: =IF(SUM(BH6:BM6)>0, 1, "")
A7: BOBEST011210H | B7: Rund- en kalfsvlees | C7: =IF(SUM(D7:I7)>0, 1, "") | J7: =IF(SUM(K7:P7)>0, 1, "") | Q7: =IF(SUM(R7:W7)>0, 1, "") | X7: =IF(SUM(Y7:AD7)>0, 1, "") | AE7: =IF(SUM(AF7:AK7)>0, 1, "") | AL7: =IF(SUM(AM7:AR7)>0, 1, "") | AS7: =IF(SUM(AT7:AY7)>0, 1, "") | AZ7: =IF(SUM(BA7:BF7)>0, 1, "") | BG7: =IF(SUM(BH7:BM7)>0, 1, "")
A8: BOBEST011220H | B8: Varkensvlees | C8: =IF(SUM(D8:I8)>0, 1, "") | J8: =IF(SUM(K8:P8)>0, 1, "") | Q8: =IF(SUM(R8:W8)>0, 1, "") | X8: =IF(SUM(Y8:AD8)>0, 1, "") | AE8: =IF(SUM(AF8:AK8)>0, 1, "") | AL8: =IF(SUM(AM8:AR8)>0, 1, "") | AS8: =IF(SUM(AT8:AY8)>0, 1, "") | AZ8: =IF(SUM(BA8:BF8)>0, 1, "") | BG8: =IF(SUM(BH8:BM8)>0, 1, "")
A9: BOBEST011240H | B9: Pluimveevlees | C9: =IF(SUM(D9:I9)>0, 1, "") | J9: =IF(SUM(K9:P9)>0, 1, "") | Q9: =IF(SUM(R9:W9)>0, 1, "") | X9: =IF(SUM(Y9:AD9)>0, 1, "") | AE9: =IF(SUM(AF9:AK9)>0, 1, "") | AL9: =IF(SUM(AM9:AR9)>0, 1, "") | AS9: =IF(SUM(AT9:AY9)>0, 1, "") | AZ9: =IF(SUM(BA9:BF9)>0, 1, "") | BG9: =IF(SUM(BH9:BM9)>0, 1, "")
A10: BOBEST011300H | B10: Vis en schaal- en schelpdieren | C10: =IF(SUM(D10:I10)>0, 1, "") | J10: =IF(SUM(K10:P10)>0, 1, "") | Q10: =IF(SUM(R10:W10)>0, 1, "") | X10: =IF(SUM(Y10:AD10)>0, 1, "") | AE10: =IF(SUM(AF10:AK10)>0, 1, "") | AL10: =IF(SUM(AM10:AR10)>0, 1, "") | AS10: =IF(SUM(AT10:AY10)>0, 1, "") | AZ10: =IF(SUM(BA10:BF10)>0, 1, "") | BG10: =IF(SUM(BH10:BM10)>0, 1, "")
A11: BOBEST011400H | B11: Melk, kaas en eieren | C11: =IF(SUM(D11:I11)>0, 1, "") | J11: =IF(SUM(K11:P11)>0, 1, "") | Q11: =IF(SUM(R11:W11)>0, 1, "") | X11: =IF(SUM(Y11:AD11)>0, 1, "") | AE11: =IF(SUM(AF11:AK11)>0, 1, "") | AL11: =IF(SUM(AM11:AR11)>0, 1, "") | AS11: =IF(SUM(AT11:AY11)>0, 1, "") | AZ11: =IF(SUM(BA11:BF11)>0, 1, "") | BG11: =IF(SUM(BH11:BM11)>0, 1, "")
A12: BOBEST011410H | B12: Verse volle melk | C12: =IF(SUM(D12:I12)>0, 1, "") | J12: =IF(SUM(K12:P12)>0, 1, "") | Q12: =IF(SUM(R12:W12)>0, 1, "") | X12: =IF(SUM(Y12:AD12)>0, 1, "") | AE12: =IF(SUM(AF12:AK12)>0, 1, "") | AL12: =IF(SUM(AM12:AR12)>0, 1, "") | AS12: =IF(SUM(AT12:AY12)>0, 1, "") | AZ12: =IF(SUM(BA12:BF12)>0, 1, "") | BG12: =IF(SUM(BH12:BM12)>0, 1, "")
A13: BOBEST011420H | B13: Verse halfvolle en magere melk | C13: =IF(SUM(D13:I13)>0, 1, "") | J13: =IF(SUM(K13:P13)>0, 1, "") | Q13: =IF(SUM(R13:W13)>0, 1, "") | X13: =IF(SUM(Y13:AD13)>0, 1, "") | AE13: =IF(SUM(AF13:AK13)>0, 1, "") | AL13: =IF(SUM(AM13:AR13)>0, 1, "") | AS13: =IF(SUM(AT13:AY13)>0, 1, "") | AZ13: =IF(SUM(BA13:BF13)>0, 1, "") | BG13: =IF(SUM(BH13:BM13)>0, 1, "")
A14: BOBEST011430H | B14: Houdbare melk | C14: =IF(SUM(D14:I14)>0, 1, "") | J14: =IF(SUM(K14:P14)>0, 1, "") | Q14: =IF(SUM(R14:W14)>0, 1, "") | X14: =IF(SUM(Y14:AD14)>0, 1, "") | AE14: =IF(SUM(AF14:AK14)>0, 1, "") | AL14: =IF(SUM(AM14:AR14)>0, 1, "") | AS14: =IF(SUM(AT14:AY14)>0, 1, "") | AZ14: =IF(SUM(BA14:BF14)>0, 1, "") | BG14: =IF(SUM(BH14:BM14)>0, 1, "")
... A28: BOBEST021300H | B28: Bier | C28: =IF(SUM(D28:I28)>0, 1, "") | J28: =IF(SUM(K28:P28)>0, 1, "") | Q28: =IF(SUM(R28:W28)>0, 1, "") | X28: =IF(SUM(Y28:AD28)>0, 1, "") | AE28: =IF(SUM(AF28:AK28)>0, 1, "") | AL28: =IF(SUM(AM28:AR28)>0, 1, "") | AS28: =IF(SUM(AT28:AY28)>0, 1, "") | AZ28: =IF(SUM(BA28:BF28)>0, 1, "") | BG28: =IF(SUM(BH28:BM28)>0, 1, "")
A29: BOBEST022000H | B29: Tabak | C29: =IF(SUM(D29:I29)>0, 1, "") -> 1 | D29: 1 | E29: 1 | F29: 1 | G29: 1 | H29: 1 | J29: =IF(SUM(K29:P29)>0, 1, "") -> 1 | K29: 1 | L29: 1 | M29: 1 | N29: 1 | O29: 1 | Q29: =IF(SUM(R29:W29)>0, 1, "") -> 1 | R29: 1 | S29: 1 | T29: 1 | U29: 1 | V29: 1 | X29: 1 | Y29: 1 | Z29: 1 | AA29: 1 | AB29: 1 | AC29: 1 | AE29: =IF(SUM(AF29:AK29)>0, 1, "") -> 1 | AF29: 1 | AG29: 1 | AH29: 1 | AI29: 1 | AJ29: 1 | AL29: =IF(SUM(AM29:AR29)>0, 1, "") -> 1 | AM29: 1 | AN29: 1 | AO29: 1 | AP29: 1 | AQ29: 1 | AS29: =IF(SUM(AT29:AY29)>0, 1, "") -> 1 | AT29: 1 | AU29: 1 | AV29: 1 | AW29: 1 | AX29: 1 | AZ29: =IF(SUM(BA29:BF29)>0, 1, "") -> 1 | BA29: 1 | BB29: 1 | BC29: 1 | BD29: 1 | BE29: 1 | BG29: =IF(SUM(BH29:BM29)>0, 1, "") -> 1 | BH29: 1 | BI29: 1 | BJ29: 1 | BK29: 1 | BL29: 1
A30: BOBEST023000H | B30: Verdovende middelen | C30: =IF(SUM(D30:I30)>0, 1, "") | J30: =IF(SUM(K30:P30)>0, 1, "") | Q30: =IF(SUM(R30:W30)>0, 1, "") | X30: =IF(SUM(Y30:AD30)>0, 1, "") | AE30: =IF(SUM(AF30:AK30)>0, 1, "") | AL30: =IF(SUM(AM30:AR30)>0, 1, "") | AS30: =IF(SUM(AT30:AY30)>0, 1, "") | AZ30: =IF(SUM(BA30:BF30)>0, 1, "") | BG30: =IF(SUM(BH30:BM30)>0, 1, "")
A31: BOBEST031100H | B31: Kledingstoffen | C31: =IF(SUM(D31:I31)>0, 1, "") | J31: =IF(SUM(K31:P31)>0, 1, "") | Q31: =IF(SUM(R31:W31)>0, 1, "") | X31: =IF(SUM(Y31:AD31)>0, 1, "") | AE31: =IF(SUM(AF31:AK31)>0, 1, "") | AL31: =IF(SUM(AM31:AR31)>0, 1, "") | AS31: =IF(SUM(AT31:AY31)>0, 1, "") | AZ31: =IF(SUM(BA31:BF31)>0, 1, "") | BG31: =IF(SUM(BH31:BM31)>0, 1, "")
A32: BOBEST031200H | B32: Kleding | C32: =IF(SUM(D32:I32)>0, 1, "") | J32: =IF(SUM(K32:P32)>0, 1, "") | Q32: =IF(SUM(R32:W32)>0, 1, "") | X32: =IF(SUM(Y32:AD32)>0, 1, "") | AE32: =IF(SUM(AF32:AK32)>0, 1, "") | AL32: =IF(SUM(AM32:AR32)>0, 1, "") | AS32: =IF(SUM(AT32:AY32)>0, 1, "") | AZ32: =IF(SUM(BA32:BF32)>0, 1, "") | BG32: =IF(SUM(BH32:BM32)>0, 1, "")
A33: BOBEST031300H | B33: Overige kledingartikelen en toebehoren | C33: =IF(SUM(D33:I33)>0, 1, "") | J33: =IF(SUM(K33:P33)>0, 1, "") | Q33: =IF(SUM(R33:W33)>0, 1, "") | X33: =IF(SUM(Y33:AD33)>0, 1, "") | AE33: =IF(SUM(AF33:AK33)>0, 1, "") | AL33: =IF(SUM(AM33:AR33)>0, 1, "") | AS33: =IF(SUM(AT33:AY33)>0, 1, "") | AZ33: =IF(SUM(BA33:BF33)>0, 1, "") | BG33: =IF(SUM(BH33:BM33)>0, 1, "")
A34: BOBEST031400H | B34: Stomen en reparatie van kleding | C34: =IF(SUM(D34:I34)>0, 1, "") | J34: =IF(SUM(K34:P34)>0, 1, "") | Q34: =IF(SUM(R34:W34)>0, 1, "") | X34: =IF(SUM(Y34:AD34)>0, 1, "") | AE34: =IF(SUM(AF34:AK34)>0, 1, "") | AL34: =IF(SUM(AM34:AR34)>0, 1, "") | AS34: =IF(SUM(AT34:AY34)>0, 1, "") | AZ34: =IF(SUM(BA34:BF34)>0, 1, "") | BG34: =IF(SUM(BH34:BM34)>0, 1, "")
A35: BOBEST032100H | B35: Schoenen en ander schoeisel | C35: =IF(SUM(D35:I35)>0, 1, "") | J35: =IF(SUM(K35:P35)>0, 1, "") | Q35: =IF(SUM(R35:W35)>0, 1, "") | X35: =IF(SUM(Y35:AD35)>0, 1, "") | AE35: =IF(SUM(AF35:AK35)>0, 1, "") | AL35: =IF(SUM(AM35:AR35)>0, 1, "") | AS35: =IF(SUM(AT35:AY35)>0, 1, "") | AZ35: =IF(SUM(BA35:BF35)>0, 1, "") | BG35: =IF(SUM(BH35:BM35)>0, 1, "")
A36: BOBEST032200H | B36: Reparatie en verhuur van schoenen | C36: =IF(SUM(D36:I36)>0, 1, "") | J36: =IF(SUM(K36:P36)>0, 1, "") | Q36: =IF(SUM(R36:W36)>0, 1, "") | X36: =IF(SUM(Y36:AD36)>0, 1, "") | AE36: =IF(SUM(AF36:AK36)>0, 1, "") | AL36: =IF(SUM(AM36:AR36)>0, 1, "") | AS36: =IF(SUM(AT36:AY36)>0, 1, "") | AZ36: =IF(SUM(BA36:BF36)>0, 1, "") | BG36: =IF(SUM(BH36:BM36)>0, 1, "")
A37: BOBEST041100H | B37: Werkelijke woninghuur betaald door huurders | C37: =IF(SUM(D37:I37)>0, 1, "") | J37: =IF(SUM(K37:P37)>0, 1, "") | Q37: =IF(SUM(R37:W37)>0, 1, "") | X37: =IF(SUM(Y37:AD37)>0, 1, "") | AE37: =IF(SUM(AF37:AK37)>0, 1, "") | AL37: =IF(SUM(AM37:AR37)>0, 1, "") | AS37: =IF(SUM(AT37:AY37)>0, 1, "") | AZ37: =IF(SUM(BA37:BF37)>0, 1, "") | BG37: =IF(SUM(BH37:BM37)>0, 1, "")
A38: BOBEST041200H | B38: Overige werkelijke woninghuur | C38: =IF(SUM(D38:I38)>0, 1, "") | J38: =IF(SUM(K38:P38)>0, 1, "") | Q38: =IF(SUM(R38:W38)>0, 1, "") | X38: =IF(SUM(Y38:AD38)>0, 1, "") | AE38: =IF(SUM(AF38:AK38)>0, 1, "") | AL38: =IF(SUM(AM38:AR38)>0, 1, "") | AS38: =IF(SUM(AT38:AY38)>0, 1, "") | AZ38: =IF(SUM(BA38:BF38)>0, 1, "") | BG38: =IF(SUM(BH38:BM38)>0, 1, "")
A39: BOBEST042100H | B39: Toegerekende huur eigen woning | C39: =IF(SUM(D39:I39)>0, 1, "") | J39: =IF(SUM(K39:P39)>0, 1, "") | Q39: =IF(SUM(R39:W39)>0, 1, "") | X39: =IF(SUM(Y39:AD39)>0, 1, "") | AE39: =IF(SUM(AF39:AK39)>0, 1, "") | AL39: =IF(SUM(AM39:AR39)>0, 1, "") | AS39: =IF(SUM(AT39:AY39)>0, 1, "") | AZ39: =IF(SUM(BA39:BF39)>0, 1, "") | BG39: =IF(SUM(BH39:BM39)>0, 1, "")
A40: BOBEST042200H | B40: Overige toegerekende huur | C40: =IF(SUM(D40:I40)>0, 1, "") | J40: =IF(SUM(K40:P40)>0, 1, "") | Q40: =IF(SUM(R40:W40)>0, 1, "") | X40: =IF(SUM(Y40:AD40)>0, 1, "") | AE40: =IF(SUM(AF40:AK40)>0, 1, "") | AL40: =IF(SUM(AM40:AR40)>0, 1, "") | AS40: =IF(SUM(AT40:AY40)>0, 1, "") | AZ40: =IF(SUM(BA40:BF40)>0, 1, "") | BG40: =IF(SUM(BH40:BM40)>0, 1, "")
A41: BOBEST043100H | B41: Onderhoudsmaterialen voor de woning | C41: =IF(SUM(D41:I41)>0, 1, "") | J41: =IF(SUM(K41:P41)>0, 1, "") | Q41: =IF(SUM(R41:W41)>0, 1, "") | X41: =IF(SUM(Y41:AD41)>0, 1, "") | AE41: =IF(SUM(AF41:AK41)>0, 1, "") | AL41: =IF(SUM(AM41:AR41)>0, 1, "") | AS41: =IF(SUM(AT41:AY41)>0, 1, "") | AZ41: =IF(SUM(BA41:BF41)>0, 1, "") | BG41: =IF(SUM(BH41:BM41)>0, 1, "")
... A75: BOBEST063000H | B75: Diensten van ziekenhuizen | C75: =IF(SUM(D75:I75)>0, 1, "") | J75: =IF(SUM(K75:P75)>0, 1, "") | Q75: =IF(SUM(R75:W75)>0, 1, "") | X75: =IF(SUM(Y75:AD75)>0, 1, "") | AE75: =IF(SUM(AF75:AK75)>0, 1, "") | AL75: =IF(SUM(AM75:AR75)>0, 1, "") | AS75: =IF(SUM(AT75:AY75)>0, 1, "") | AZ75: =IF(SUM(BA75:BF75)>0, 1, "") | BG75: =IF(SUM(BH75:BM75)>0, 1, "")
A76: BOBEST071100H | B76: Auto's | C76: =IF(SUM(D76:I76)>0, 1, "") -> 1 | G76: 1 | J76: =IF(SUM(K76:P76)>0, 1, "") -> 1 | N76: 1 | Q76: =IF(SUM(R76:W76)>0, 1, "") -> 1 | U76: 1 | X76: =IF(SUM(Y76:AD76)>0, 1, "") -> 1 | AB76: 1 | AE76: =IF(SUM(AF76:AK76)>0, 1, "") -> 1 | AI76: 1 | AL76: =IF(SUM(AM76:AR76)>0, 1, "") -> 1 | AP76: 1 | AS76: =IF(SUM(AT76:AY76)>0, 1, "") -> 1 | AW76: 1 | AZ76: =IF(SUM(BA76:BF76)>0, 1, "") -> 1 | BD76: 1 | BG76: =IF(SUM(BH76:BM76)>0, 1, "") -> 1 | BK76: 1
A77: BOBEST071200H | B77: Motoren, brom- en elektrische fietsen | C77: =IF(SUM(D77:I77)>0, 1, "") -> 1 | F77: 1 | J77: =IF(SUM(K77:P77)>0, 1, "") -> 1 | M77: 1 | Q77: =IF(SUM(R77:W77)>0, 1, "") -> 1 | T77: 1 | X77: =IF(SUM(Y77:AD77)>0, 1, "") -> 1 | AA77: 1 | AE77: =IF(SUM(AF77:AK77)>0, 1, "") -> 1 | AH77: 1 | AL77: =IF(SUM(AM77:AR77)>0, 1, "") -> 1 | AO77: 1 | AS77: =IF(SUM(AT77:AY77)>0, 1, "") -> 1 | AV77: 1 | AZ77: =IF(SUM(BA77:BF77)>0, 1, "") -> 1 | BC77: 1 | BG77: =IF(SUM(BH77:BM77)>0, 1, "") -> 1 | BJ77: 1
A78: BOBEST071300H | B78: Fietsen | C78: =IF(SUM(D78:I78)>0, 1, "") -> 1 | E78: 1 | J78: =IF(SUM(K78:P78)>0, 1, "") -> 1 | L78: 1 | Q78: =IF(SUM(R78:W78)>0, 1, "") -> 1 | S78: 1 | X78: =IF(SUM(Y78:AD78)>0, 1, "") -> 1 | Z78: 1 | AE78: =IF(SUM(AF78:AK78)>0, 1, "") -> 1 | AG78: 1 | AL78: =IF(SUM(AM78:AR78)>0, 1, "") -> 1 | AN78: 1 | AS78: =IF(SUM(AT78:AY78)>0, 1, "") -> 1 | AU78: 1 | AZ78: =IF(SUM(BA78:BF78)>0, 1, "") -> 1 | BB78: 1 | BG78: =IF(SUM(BH78:BM78)>0, 1, "") -> 1 | BI78: 1
A79: BOBEST071400H | B79: Door dieren getrokken voertuigen | C79: =IF(SUM(D79:I79)>0, 1, "") | J79: =IF(SUM(K79:P79)>0, 1, "") | Q79: =IF(SUM(R79:W79)>0, 1, "") | X79: =IF(SUM(Y79:AD79)>0, 1, "") | AE79: =IF(SUM(AF79:AK79)>0, 1, "") | AL79: =IF(SUM(AM79:AR79)>0, 1, "") | AS79: =IF(SUM(AT79:AY79)>0, 1, "") | AZ79: =IF(SUM(BA79:BF79)>0, 1, "") | BG79: =IF(SUM(BH79:BM79)>0, 1, "")
A80: BOBEST072100H | B80: Benodigdheden privé-voertuigen | C80: =IF(SUM(D80:I80)>0, 1, "") -> 1 | F80: 1 | G80: 1 | H80: 1 | J80: =IF(SUM(K80:P80)>0, 1, "") -> 1 | M80: 1 | N80: 1 | O80: 1 | Q80: =IF(SUM(R80:W80)>0, 1, "") -> 1 | T80: 1 | U80: 1 | V80: 1 | X80: =IF(SUM(Y80:AD80)>0, 1, "") -> 1 | AA80: 1 | AB80: 1 | AC80: 1 | AE80: =IF(SUM(AF80:AK80)>0, 1, "") -> 1 | AH80: 1 | AI80: 1 | AJ80: 1 | AL80: =IF(SUM(AM80:AR80)>0, 1, "") -> 1 | AO80: 1 | AP80: 1 | AQ80: 1 | AS80: =IF(SUM(AT80:AY80)>0, 1, "") -> 1 | AV80: 1 | AW80: 1 | AX80: 1 | AZ80: =IF(SUM(BA80:BF80)>0, 1, "") -> 1 | BC80: 1 | BD80: 1 | BE80: 1 | BG80: =IF(SUM(BH80:BM80)>0, 1, "") -> 1 | BJ80: 1 | BK80: 1 | BL80: 1
A81: BOBEST072200H | B81: Brandstoffen en smeermiddelen | C81: =IF(SUM(D81:I81)>0, 1, "") -> 1 | F81: 1 | G81: 1 | H81: 1 | J81: =IF(SUM(K81:P81)>0, 1, "") -> 1 | M81: 1 | N81: 1 | O81: 1 | Q81: =IF(SUM(R81:W81)>0, 1, "") -> 1 | T81: 1 | U81: 1 | V81: 1 | X81: =IF(SUM(Y81:AD81)>0, 1, "") -> 1 | AA81: 1 | AB81: 1 | AC81: 1 | AE81: =IF(SUM(AF81:AK81)>0, 1, "") -> 1 | AH81: 1 | AI81: 1 | AJ81: 1 | AL81: =IF(SUM(AM81:AR81)>0, 1, "") -> 1 | AO81: 1 | AP81: 1 | AQ81: 1 | AS81: =IF(SUM(AT81:AY81)>0, 1, "") -> 1 | AV81: 1 | AW81: 1 | AX81: 1 | AZ81: =IF(SUM(BA81:BF81)>0, 1, "") -> 1 | BC81: 1 | BD81: 1 | BE81: 1 | BG81: =IF(SUM(BH81:BM81)>0, 1, "") -> 1 | BJ81: 1 | BK81: 1 | BL81: 1
A82: BOBEST072300H | B82: Onderhoud en reparatie privé-voertuigen | C82: =IF(SUM(D82:I82)>0, 1, "") | J82: =IF(SUM(K82:P82)>0, 1, "") | Q82: =IF(SUM(R82:W82)>0, 1, "") | X82: =IF(SUM(Y82:AD82)>0, 1, "") | AE82: =IF(SUM(AF82:AK82)>0, 1, "") | AL82: =IF(SUM(AM82:AR82)>0, 1, "") | AS82: =IF(SUM(AT82:AY82)>0, 1, "") | AZ82: =IF(SUM(BA82:BF82)>0, 1, "") | BG82: =IF(SUM(BH82:BM82)>0, 1, "")
A83: BOBEST072400H | B83: Overige diensten privé-voertuigen | C83: =IF(SUM(D83:I83)>0, 1, "") | J83: =IF(SUM(K83:P83)>0, 1, "") | Q83: =IF(SUM(R83:W83)>0, 1, "") | X83: =IF(SUM(Y83:AD83)>0, 1, "") | AE83: =IF(SUM(AF83:AK83)>0, 1, "") | AL83: =IF(SUM(AM83:AR83)>0, 1, "") | AS83: =IF(SUM(AT83:AY83)>0, 1, "") | AZ83: =IF(SUM(BA83:BF83)>0, 1, "") | BG83: =IF(SUM(BH83:BM83)>0, 1, "")
A84: BOBEST073100H | B84: Personenvervoer per spoor | C84: =IF(SUM(D84:I84)>0, 1, "") -> 1 | I84: 1 | J84: =IF(SUM(K84:P84)>0, 1, "") -> 1 | P84: 1 | Q84: =IF(SUM(R84:W84)>0, 1, "") -> 1 | W84: 1 | X84: =IF(SUM(Y84:AD84)>0, 1, "") -> 1 | AD84: 1 | AE84: =IF(SUM(AF84:AK84)>0, 1, "") -> 1 | AK84: 1 | AL84: =IF(SUM(AM84:AR84)>0, 1, "") -> 1 | AR84: 1 | AS84: =IF(SUM(AT84:AY84)>0, 1, "") -> 1 | AY84: 1 | AZ84: =IF(SUM(BA84:BF84)>0, 1, "") -> 1 | BF84: 1 | BG84: =IF(SUM(BH84:BM84)>0, 1, "") -> 1 | BM84: 1
A85: BOBEST073200H | B85: Personenvervoer over de weg | C85: =IF(SUM(D85:I85)>0, 1, "") -> 1 | I85: 1 | J85: =IF(SUM(K85:P85)>0, 1, "") -> 1 | P85: 1 | Q85: =IF(SUM(R85:W85)>0, 1, "") -> 1 | W85: 1 | X85: =IF(SUM(Y85:AD85)>0, 1, "") -> 1 | AD85: 1 | AE85: =IF(SUM(AF85:AK85)>0, 1, "") -> 1 | AK85: 1 | AL85: =IF(SUM(AM85:AR85)>0, 1, "") -> 1 | AR85: 1 | AS85: =IF(SUM(AT85:AY85)>0, 1, "") -> 1 | AY85: 1 | AZ85: =IF(SUM(BA85:BF85)>0, 1, "") -> 1 | BF85: 1 | BG85: =IF(SUM(BH85:BM85)>0, 1, "") -> 1 | BM85: 1
A86: BOBEST073300H | B86: Personenvervoer door de lucht | C86: =IF(SUM(D86:I86)>0, 1, "") -> 1 | I86: 1 | J86: =IF(SUM(K86:P86)>0, 1, "") -> 1 | P86: 1 | Q86: =IF(SUM(R86:W86)>0, 1, "") -> 1 | W86: 1 | X86: =IF(SUM(Y86:AD86)>0, 1, "") -> 1 | AD86: 1 | AE86: =IF(SUM(AF86:AK86)>0, 1, "") -> 1 | AK86: 1 | AL86: =IF(SUM(AM86:AR86)>0, 1, "") -> 1 | AR86: 1 | AS86: =IF(SUM(AT86:AY86)>0, 1, "") -> 1 | AY86: 1 | AZ86: =IF(SUM(BA86:BF86)>0, 1, "") -> 1 | BF86: 1 | BG86: =IF(SUM(BH86:BM86)>0, 1, "") -> 1 | BM86: 1
...

Sheet mapping_intercept
A1: Variable | C1: Intercept
A3: BOBEST011100H | B3: Brood en granen
A4: BOBEST011110H | B4: Rijst
A5: BOBEST011170H | B5: Ontbijtgranen
A6: BOBEST011200H | B6: Vlees
A7: BOBEST011210H | B7: Rund- en kalfsvlees
A8: BOBEST011220H | B8: Varkensvlees
A9: BOBEST011240H | B9: Pluimveevlees
A10: BOBEST011300H | B10: Vis en schaal- en schelpdieren
A11: BOBEST011400H | B11: Melk, kaas en eieren
A12: BOBEST011410H | B12: Verse volle melk
A13: BOBEST011420H | B13: Verse halfvolle en magere melk
A14: BOBEST011430H | B14: Houdbare melk
... A158: BOBEST300000H | B158: Uitgaven aan groot onderhoud

Sheet emissions
A1: variable | B1: emissions
A2: BOBEST011100H
A3: BOBEST011110H
A4: BOBEST011170H
A5: BOBEST011200H
A6: BOBEST011210H
A7: BOBEST011220H
A8: BOBEST011240H
A9: BOBEST011300H
A10: BOBEST011400H
A11: BOBEST011410H
A12: BOBEST011420H
A13: BOBEST011430H
... A158: total
